D:\PythonProject\Time_series_anomaly_detection\weights\2022_02_04 21_25_50
series:  0      29.9
1      30.6
2      24.8
3      37.2
4      21.0
       ...
304    41.7
305    35.3
306     0.0
307    39.8
308    41.9
Name: concentration, Length: 309, dtype: float64
Traceback (most recent call last):
  File "train.py", line 133, in <module>
    main(args)
  File "train.py", line 80, in main
    train_data, val_data, timestamp = get_data(input_window, output_window, device=device)
  File "D:\PythonProject\Time_series_anomaly_detection\utils\data_prepare.py", line 38, in get_data
    timestamp = series['date']
  File "D:\miniconda\envs\pytorch\lib\site-packages\pandas\core\series.py", line 942, in __getitem__
    return self._get_value(key)
  File "D:\miniconda\envs\pytorch\lib\site-packages\pandas\core\series.py", line 1051, in _get_value
    loc = self.index.get_loc(label)
  File "D:\miniconda\envs\pytorch\lib\site-packages\pandas\core\indexes\range.py", line 388, in get_loc
    raise KeyError(key)
KeyError: 'date'