2022-02-04 03:24:10,335 INFO    MainThread:19236 [internal.py:wandb_internal():90] W&B internal server running at pid: 19236, started at: 2022-02-04 03:24:10.335691
2022-02-04 03:24:10,339 INFO    WriterThread:19236 [datastore.py:open_for_write():77] open: D:\PythonProject\Time_series_anomaly_detection\wandb\run-20220204_032408-13iwdsrc\run-13iwdsrc.wandb
2022-02-04 03:24:10,339 DEBUG   HandlerThread:19236 [handler.py:handle_request():130] handle_request: check_version
2022-02-04 03:24:10,341 DEBUG   SenderThread:19236 [sender.py:send():234] send: header
2022-02-04 03:24:10,341 DEBUG   SenderThread:19236 [sender.py:send_request():248] send_request: check_version
2022-02-04 03:24:10,363 DEBUG   SenderThread:19236 [sender.py:send():234] send: run
2022-02-04 03:24:14,101 ERROR   SenderThread:19236 [retry.py:__call__():126] Retry attempt failed:
Traceback (most recent call last):
  File "D:\miniconda\envs\pytorch\lib\site-packages\urllib3\connectionpool.py", line 700, in urlopen
    self._prepare_proxy(conn)
  File "D:\miniconda\envs\pytorch\lib\site-packages\urllib3\connectionpool.py", line 994, in _prepare_proxy
    conn.connect()
  File "D:\miniconda\envs\pytorch\lib\site-packages\urllib3\connection.py", line 364, in connect
    conn = self._connect_tls_proxy(hostname, conn)
  File "D:\miniconda\envs\pytorch\lib\site-packages\urllib3\connection.py", line 507, in _connect_tls_proxy
    ssl_context=ssl_context,
  File "D:\miniconda\envs\pytorch\lib\site-packages\urllib3\util\ssl_.py", line 453, in ssl_wrap_socket
    ssl_sock = _ssl_wrap_socket_impl(sock, context, tls_in_tls)
  File "D:\miniconda\envs\pytorch\lib\site-packages\urllib3\util\ssl_.py", line 495, in _ssl_wrap_socket_impl
    return ssl_context.wrap_socket(sock)
  File "D:\miniconda\envs\pytorch\lib\ssl.py", line 423, in wrap_socket
    session=session
  File "D:\miniconda\envs\pytorch\lib\ssl.py", line 870, in _create
    self.do_handshake()
  File "D:\miniconda\envs\pytorch\lib\ssl.py", line 1139, in do_handshake
    self._sslobj.do_handshake()
OSError: [Errno 0] Error

During handling of the above exception, another exception occurred:

Traceback (most recent call last):
  File "D:\miniconda\envs\pytorch\lib\site-packages\requests\adapters.py", line 450, in send
    timeout=timeout
  File "D:\miniconda\envs\pytorch\lib\site-packages\urllib3\connectionpool.py", line 786, in urlopen
    method, url, error=e, _pool=self, _stacktrace=sys.exc_info()[2]
  File "D:\miniconda\envs\pytorch\lib\site-packages\urllib3\util\retry.py", line 592, in increment
    raise MaxRetryError(_pool, url, error or ResponseError(cause))
urllib3.exceptions.MaxRetryError: HTTPSConnectionPool(host='api.wandb.ai', port=443): Max retries exceeded with url: /graphql (Caused by ProxyError('Cannot connect to proxy.', OSError(0, 'Error')))

During handling of the above exception, another exception occurred:

Traceback (most recent call last):
  File "D:\miniconda\envs\pytorch\lib\site-packages\wandb\sdk\lib\retry.py", line 102, in __call__
    result = self._call_fn(*args, **kwargs)
  File "D:\miniconda\envs\pytorch\lib\site-packages\wandb\sdk\internal\internal_api.py", line 141, in execute
    return self.client.execute(*args, **kwargs)
  File "D:\miniconda\envs\pytorch\lib\site-packages\wandb\vendor\gql-0.2.0\gql\client.py", line 52, in execute
    result = self._get_result(document, *args, **kwargs)
  File "D:\miniconda\envs\pytorch\lib\site-packages\wandb\vendor\gql-0.2.0\gql\client.py", line 60, in _get_result
    return self.transport.execute(document, *args, **kwargs)
  File "D:\miniconda\envs\pytorch\lib\site-packages\wandb\vendor\gql-0.2.0\gql\transport\requests.py", line 38, in execute
    request = requests.post(self.url, **post_args)
  File "D:\miniconda\envs\pytorch\lib\site-packages\requests\api.py", line 117, in post
    return request('post', url, data=data, json=json, **kwargs)
  File "D:\miniconda\envs\pytorch\lib\site-packages\requests\api.py", line 61, in request
    return session.request(method=method, url=url, **kwargs)
  File "D:\miniconda\envs\pytorch\lib\site-packages\requests\sessions.py", line 529, in request
    resp = self.send(prep, **send_kwargs)
  File "D:\miniconda\envs\pytorch\lib\site-packages\requests\sessions.py", line 645, in send
    r = adapter.send(request, **kwargs)
  File "D:\miniconda\envs\pytorch\lib\site-packages\requests\adapters.py", line 513, in send
    raise ProxyError(e, request=request)
requests.exceptions.ProxyError: HTTPSConnectionPool(host='api.wandb.ai', port=443): Max retries exceeded with url: /graphql (Caused by ProxyError('Cannot connect to proxy.', OSError(0, 'Error')))
2022-02-04 03:24:40,378 DEBUG   HandlerThread:19236 [handler.py:handle_request():130] handle_request: shutdown
2022-02-04 03:24:40,379 INFO    HandlerThread:19236 [handler.py:finish():731] shutting down handler
2022-02-04 03:24:40,615 INFO    WriterThread:19236 [datastore.py:close():281] close: D:\PythonProject\Time_series_anomaly_detection\wandb\run-20220204_032408-13iwdsrc\run-13iwdsrc.wandb
2022-02-04 03:24:43,734 INFO    SenderThread:19236 [dir_watcher.py:__init__():169] watching files in: D:\PythonProject\Time_series_anomaly_detection\wandb\run-20220204_032408-13iwdsrc\files
2022-02-04 03:24:43,734 INFO    SenderThread:19236 [sender.py:_start_run_threads():807] run started: 13iwdsrc with start time 1643916248
2022-02-04 03:24:43,735 INFO    SenderThread:19236 [sender.py:finish():1070] shutting down sender
2022-02-04 03:24:43,735 INFO    SenderThread:19236 [dir_watcher.py:finish():283] shutting down directory watcher
2022-02-04 03:24:44,740 INFO    SenderThread:19236 [dir_watcher.py:finish():313] scan: D:\PythonProject\Time_series_anomaly_detection\wandb\run-20220204_032408-13iwdsrc\files
2022-02-04 03:24:44,741 INFO    SenderThread:19236 [dir_watcher.py:finish():327] scan save: D:\PythonProject\Time_series_anomaly_detection\wandb\run-20220204_032408-13iwdsrc\files\config.yaml config.yaml
2022-02-04 03:24:44,742 INFO    SenderThread:19236 [file_pusher.py:finish():177] shutting down file pusher
2022-02-04 03:24:44,742 INFO    SenderThread:19236 [file_pusher.py:join():182] waiting for file pusher
2022-02-04 03:24:45,602 INFO    Thread-14 :19236 [upload_job.py:push():137] Uploaded file D:\PythonProject\Time_series_anomaly_detection\wandb\run-20220204_032408-13iwdsrc\files\config.yaml
2022-02-04 03:24:46,618 INFO    MainThread:19236 [internal.py:handle_exit():77] Internal process exited
