2022-02-04 22:43:21,297 INFO    MainThread:18020 [internal.py:wandb_internal():90] W&B internal server running at pid: 18020, started at: 2022-02-04 22:43:21.296724
2022-02-04 22:43:21,300 INFO    WriterThread:18020 [datastore.py:open_for_write():77] open: D:\PythonProject\Time_series_anomaly_detection\wandb\run-20220204_224318-jdj3v60l\run-jdj3v60l.wandb
2022-02-04 22:43:21,300 DEBUG   HandlerThread:18020 [handler.py:handle_request():130] handle_request: check_version
2022-02-04 22:43:21,303 DEBUG   SenderThread:18020 [sender.py:send():234] send: header
2022-02-04 22:43:21,303 DEBUG   SenderThread:18020 [sender.py:send_request():248] send_request: check_version
2022-02-04 22:43:22,739 WARNING MainThread:18020 [internal.py:wandb_internal():146] Internal process interrupt: 1
2022-02-04 22:43:23,406 WARNING MainThread:18020 [internal.py:wandb_internal():146] Internal process interrupt: 2
2022-02-04 22:43:23,407 ERROR   MainThread:18020 [internal.py:wandb_internal():149] Internal process interrupted.
2022-02-04 22:43:24,228 INFO    SenderThread:18020 [sender.py:finish():1070] shutting down sender
2022-02-04 22:43:24,321 INFO    HandlerThread:18020 [handler.py:finish():731] shutting down handler
2022-02-04 22:43:24,323 INFO    WriterThread:18020 [datastore.py:close():281] close: D:\PythonProject\Time_series_anomaly_detection\wandb\run-20220204_224318-jdj3v60l\run-jdj3v60l.wandb
2022-02-04 22:43:24,324 INFO    MainThread:18020 [internal.py:handle_exit():77] Internal process exited
