2022-02-01 17:26:35,629 INFO    MainThread:10788 [internal.py:wandb_internal():90] W&B internal server running at pid: 10788, started at: 2022-02-01 17:26:35.627368
2022-02-01 17:26:35,632 INFO    WriterThread:10788 [datastore.py:open_for_write():77] open: D:\PythonProject\Time_series_anomaly_detection\wandb\run-20220201_172633-wae268vf\run-wae268vf.wandb
2022-02-01 17:26:35,632 DEBUG   HandlerThread:10788 [handler.py:handle_request():130] handle_request: check_version
2022-02-01 17:26:35,636 DEBUG   SenderThread:10788 [sender.py:send():234] send: header
2022-02-01 17:26:35,636 DEBUG   SenderThread:10788 [sender.py:send_request():248] send_request: check_version
2022-02-01 17:26:35,668 DEBUG   SenderThread:10788 [sender.py:send():234] send: run
2022-02-01 17:26:36,367 WARNING MainThread:10788 [internal.py:wandb_internal():146] Internal process interrupt: 1
2022-02-01 17:26:37,540 WARNING MainThread:10788 [internal.py:wandb_internal():146] Internal process interrupt: 2
2022-02-01 17:26:37,540 ERROR   MainThread:10788 [internal.py:wandb_internal():149] Internal process interrupted.
2022-02-01 17:26:37,681 INFO    WriterThread:10788 [datastore.py:close():281] close: D:\PythonProject\Time_series_anomaly_detection\wandb\run-20220201_172633-wae268vf\run-wae268vf.wandb
2022-02-01 17:26:37,681 INFO    HandlerThread:10788 [handler.py:finish():731] shutting down handler
2022-02-01 17:26:39,065 ERROR   SenderThread:10788 [retry.py:__call__():126] Retry attempt failed:
Traceback (most recent call last):
  File "D:\miniconda\envs\pytorch\lib\site-packages\urllib3\connectionpool.py", line 700, in urlopen
    self._prepare_proxy(conn)
  File "D:\miniconda\envs\pytorch\lib\site-packages\urllib3\connectionpool.py", line 994, in _prepare_proxy
    conn.connect()
  File "D:\miniconda\envs\pytorch\lib\site-packages\urllib3\connection.py", line 364, in connect
    conn = self._connect_tls_proxy(hostname, conn)
  File "D:\miniconda\envs\pytorch\lib\site-packages\urllib3\connection.py", line 507, in _connect_tls_proxy
    ssl_context=ssl_context,
  File "D:\miniconda\envs\pytorch\lib\site-packages\urllib3\util\ssl_.py", line 453, in ssl_wrap_socket
    ssl_sock = _ssl_wrap_socket_impl(sock, context, tls_in_tls)
  File "D:\miniconda\envs\pytorch\lib\site-packages\urllib3\util\ssl_.py", line 495, in _ssl_wrap_socket_impl
    return ssl_context.wrap_socket(sock)
  File "D:\miniconda\envs\pytorch\lib\ssl.py", line 423, in wrap_socket
    session=session
  File "D:\miniconda\envs\pytorch\lib\ssl.py", line 870, in _create
    self.do_handshake()
  File "D:\miniconda\envs\pytorch\lib\ssl.py", line 1139, in do_handshake
    self._sslobj.do_handshake()
OSError: [Errno 0] Error

During handling of the above exception, another exception occurred:

Traceback (most recent call last):
  File "D:\miniconda\envs\pytorch\lib\site-packages\requests\adapters.py", line 450, in send
    timeout=timeout
  File "D:\miniconda\envs\pytorch\lib\site-packages\urllib3\connectionpool.py", line 786, in urlopen
    method, url, error=e, _pool=self, _stacktrace=sys.exc_info()[2]
  File "D:\miniconda\envs\pytorch\lib\site-packages\urllib3\util\retry.py", line 592, in increment
    raise MaxRetryError(_pool, url, error or ResponseError(cause))
urllib3.exceptions.MaxRetryError: HTTPSConnectionPool(host='api.wandb.ai', port=443): Max retries exceeded with url: /graphql (Caused by ProxyError('Cannot connect to proxy.', OSError(0, 'Error')))

During handling of the above exception, another exception occurred:

Traceback (most recent call last):
  File "D:\miniconda\envs\pytorch\lib\site-packages\wandb\sdk\lib\retry.py", line 102, in __call__
    result = self._call_fn(*args, **kwargs)
  File "D:\miniconda\envs\pytorch\lib\site-packages\wandb\sdk\internal\internal_api.py", line 141, in execute
    return self.client.execute(*args, **kwargs)
  File "D:\miniconda\envs\pytorch\lib\site-packages\wandb\vendor\gql-0.2.0\gql\client.py", line 52, in execute
    result = self._get_result(document, *args, **kwargs)
  File "D:\miniconda\envs\pytorch\lib\site-packages\wandb\vendor\gql-0.2.0\gql\client.py", line 60, in _get_result
    return self.transport.execute(document, *args, **kwargs)
  File "D:\miniconda\envs\pytorch\lib\site-packages\wandb\vendor\gql-0.2.0\gql\transport\requests.py", line 38, in execute
    request = requests.post(self.url, **post_args)
  File "D:\miniconda\envs\pytorch\lib\site-packages\requests\api.py", line 117, in post
    return request('post', url, data=data, json=json, **kwargs)
  File "D:\miniconda\envs\pytorch\lib\site-packages\requests\api.py", line 61, in request
    return session.request(method=method, url=url, **kwargs)
  File "D:\miniconda\envs\pytorch\lib\site-packages\requests\sessions.py", line 529, in request
    resp = self.send(prep, **send_kwargs)
  File "D:\miniconda\envs\pytorch\lib\site-packages\requests\sessions.py", line 645, in send
    r = adapter.send(request, **kwargs)
  File "D:\miniconda\envs\pytorch\lib\site-packages\requests\adapters.py", line 513, in send
    raise ProxyError(e, request=request)
requests.exceptions.ProxyError: HTTPSConnectionPool(host='api.wandb.ai', port=443): Max retries exceeded with url: /graphql (Caused by ProxyError('Cannot connect to proxy.', OSError(0, 'Error')))
